<?xml version="1.0" ?>
<!-- Generated using onshape-to-robot -->
<!-- Onshape document_id: 77ae2a3fa2dfa0e3fa6e957b -->
<robot name="gripper">
  <!-- Link 42_step_motor -->
  <link name="42_step_motor">
    <inertial>
      <origin xyz="0 0 0" rpy="0 0 0"/>
      <mass value="1e-09"/>
      <inertia ixx="1e-09" ixy="0" ixz="0" iyy="1e-09" iyz="0" izz="1e-09"/>
    </inertial>
    <!-- Part 42_step_motor -->
    <visual>
      <origin xyz="-0.00924528 -0.0810901 0.034284" rpy="-1.5708 -0 0"/>
      <geometry>
        <mesh filename="package://gripper_description/meshes/42_step_motor.stl"/>
      </geometry>
      <material name="42_step_motor_material">
        <color rgba="0.501961 0.501961 0.501961 1"/>
      </material>
    </visual>
    <collision>
      <origin xyz="-0.00924528 -0.0810901 0.034284" rpy="-1.5708 -0 0"/>
      <geometry>
        <mesh filename="package://gripper_description/meshes/42_step_motor.stl"/>
      </geometry>
    </collision>
    <!-- Part fa3_main_body -->
    <visual>
      <origin xyz="-0.00924528 -0.0810901 0.033684" rpy="-1.5708 -0 0"/>
      <geometry>
        <mesh filename="package://gripper_description/meshes/fa3_main_body.stl"/>
      </geometry>
      <material name="fa3_main_body_material">
        <color rgba="0.372549 0.372549 0.372549 1"/>
      </material>
    </visual>
    <collision>
      <origin xyz="-0.00924528 -0.0810901 0.033684" rpy="-1.5708 -0 0"/>
      <geometry>
        <mesh filename="package://gripper_description/meshes/fa3_main_body.stl"/>
      </geometry>
    </collision>
  </link>
  <!-- Frame closing_link_1_3_1 (dummy link + fixed joint) -->
  <link name="closing_link_1_3_1">
    <origin xyz="0 0 0" rpy="0 -0 0"/>
    <inertial>
      <origin xyz="0 0 0" rpy="0 0 0"/>
      <mass value="1e-9"/>
      <inertia ixx="0" ixy="0" ixz="0" iyy="0" iyz="0" izz="0"/>
    </inertial>
  </link>
  <joint name="closing_link_1_3_1_frame" type="fixed">
    <origin xyz="0.004 0.0275 0.079" rpy="-0 1.5708 0"/>
    <parent link="42_step_motor"/>
    <child link="closing_link_1_3_1"/>
    <axis xyz="0 0 0"/>
  </joint>
  <!-- Frame closing_link_1_3_1_z (dummy link + fixed joint) -->
  <link name="closing_link_1_3_1_z">
    <origin xyz="0 0 0" rpy="0 -0 0"/>
    <inertial>
      <origin xyz="0 0 0" rpy="0 0 0"/>
      <mass value="1e-9"/>
      <inertia ixx="0" ixy="0" ixz="0" iyy="0" iyz="0" izz="0"/>
    </inertial>
  </link>
  <joint name="closing_link_1_3_1_z_frame" type="fixed">
    <origin xyz="0.104 0.0275 0.079" rpy="-0 1.5708 0"/>
    <parent link="42_step_motor"/>
    <child link="closing_link_1_3_1_z"/>
    <axis xyz="0 0 0"/>
  </joint>
  <!-- Frame closing_link_2_3_2 (dummy link + fixed joint) -->
  <link name="closing_link_2_3_2">
    <origin xyz="0 0 0" rpy="0 -0 0"/>
    <inertial>
      <origin xyz="0 0 0" rpy="0 0 0"/>
      <mass value="1e-9"/>
      <inertia ixx="0" ixy="0" ixz="0" iyy="0" iyz="0" izz="0"/>
    </inertial>
  </link>
  <joint name="closing_link_2_3_2_frame" type="fixed">
    <origin xyz="-0.0258157 -0.0102859 0.079" rpy="1.5708 -0 0.523599"/>
    <parent link="42_step_motor"/>
    <child link="closing_link_2_3_2"/>
    <axis xyz="0 0 0"/>
  </joint>
  <!-- Frame closing_link_2_3_2_z (dummy link + fixed joint) -->
  <link name="closing_link_2_3_2_z">
    <origin xyz="0 0 0" rpy="0 -0 0"/>
    <inertial>
      <origin xyz="0 0 0" rpy="0 0 0"/>
      <mass value="1e-9"/>
      <inertia ixx="0" ixy="0" ixz="0" iyy="0" iyz="0" izz="0"/>
    </inertial>
  </link>
  <joint name="closing_link_2_3_2_z_frame" type="fixed">
    <origin xyz="0.0241843 -0.0968884 0.079" rpy="1.5708 -0 0.523599"/>
    <parent link="42_step_motor"/>
    <child link="closing_link_2_3_2_z"/>
    <axis xyz="0 0 0"/>
  </joint>
  <!-- Frame closing_link_3_3_1 (dummy link + fixed joint) -->
  <link name="closing_link_3_3_1">
    <origin xyz="0 0 0" rpy="0 -0 0"/>
    <inertial>
      <origin xyz="0 0 0" rpy="0 0 0"/>
      <mass value="1e-9"/>
      <inertia ixx="0" ixy="0" ixz="0" iyy="0" iyz="0" izz="0"/>
    </inertial>
  </link>
  <joint name="closing_link_3_3_1_frame" type="fixed">
    <origin xyz="0.0258157 -0.0102859 0.079" rpy="-1.5708 -0 -0.523599"/>
    <parent link="42_step_motor"/>
    <child link="closing_link_3_3_1"/>
    <axis xyz="0 0 0"/>
  </joint>
  <!-- Frame closing_link_3_3_1_z (dummy link + fixed joint) -->
  <link name="closing_link_3_3_1_z">
    <origin xyz="0 0 0" rpy="0 -0 0"/>
    <inertial>
      <origin xyz="0 0 0" rpy="0 0 0"/>
      <mass value="1e-9"/>
      <inertia ixx="0" ixy="0" ixz="0" iyy="0" iyz="0" izz="0"/>
    </inertial>
  </link>
  <joint name="closing_link_3_3_1_z_frame" type="fixed">
    <origin xyz="0.0758157 0.0763166 0.079" rpy="-1.5708 -0 -0.523599"/>
    <parent link="42_step_motor"/>
    <child link="closing_link_3_3_1_z"/>
    <axis xyz="0 0 0"/>
  </joint>
  <!-- Frame eef (dummy link + fixed joint) -->
  <link name="eef">
    <origin xyz="0 0 0" rpy="0 -0 0"/>
    <inertial>
      <origin xyz="0 0 0" rpy="0 0 0"/>
      <mass value="1e-9"/>
      <inertia ixx="0" ixy="0" ixz="0" iyy="0" iyz="0" izz="0"/>
    </inertial>
  </link>
  <joint name="eef_frame" type="fixed">
    <origin xyz="1.26635e-16 -6.93889e-17 0.184" rpy="0 -0 0"/>
    <parent link="42_step_motor"/>
    <child link="eef"/>
    <axis xyz="0 0 0"/>
  </joint>
  <!-- Link 42_motor_nut -->
  <link name="42_motor_nut">
    <inertial>
      <origin xyz="0 0 0" rpy="0 0 0"/>
      <mass value="1e-09"/>
      <inertia ixx="1e-09" ixy="0" ixz="0" iyy="1e-09" iyz="0" izz="1e-09"/>
    </inertial>
    <!-- Part fa3_driveboard -->
    <visual>
      <origin xyz="-0.00924528 -0.0810901 0.0190666" rpy="-1.5708 -4.90029e-16 0"/>
      <geometry>
        <mesh filename="package://gripper_description/meshes/fa3_driveboard.stl"/>
      </geometry>
      <material name="fa3_driveboard_material">
        <color rgba="0.309804 0.309804 0.309804 1"/>
      </material>
    </visual>
    <collision>
      <origin xyz="-0.00924528 -0.0810901 0.0190666" rpy="-1.5708 -4.90029e-16 0"/>
      <geometry>
        <mesh filename="package://gripper_description/meshes/fa3_driveboard.stl"/>
      </geometry>
    </collision>
    <!-- Part 42_motor_nut -->
    <visual>
      <origin xyz="-0.00924528 -0.0810901 0.0190666" rpy="-1.5708 -0 0"/>
      <geometry>
        <mesh filename="package://gripper_description/meshes/42_motor_nut.stl"/>
      </geometry>
      <material name="42_motor_nut_material">
        <color rgba="1 0.952941 0.380392 1"/>
      </material>
    </visual>
    <collision>
      <origin xyz="-0.00924528 -0.0810901 0.0190666" rpy="-1.5708 -0 0"/>
      <geometry>
        <mesh filename="package://gripper_description/meshes/42_motor_nut.stl"/>
      </geometry>
    </collision>
  </link>
  <!-- Link fa3_link_2 -->
  <link name="fa3_link_2">
    <inertial>
      <origin xyz="0 0 0" rpy="0 0 0"/>
      <mass value="1e-09"/>
      <inertia ixx="1e-09" ixy="0" ixz="0" iyy="1e-09" iyz="0" izz="1e-09"/>
    </inertial>
    <!-- Part fa3_link_2 -->
    <visual>
      <origin xyz="-0.0147666 0.12609 0.00524528" rpy="1.5708 1.5708 0"/>
      <geometry>
        <mesh filename="package://gripper_description/meshes/fa3_link_2.stl"/>
      </geometry>
      <material name="fa3_link_2_material">
        <color rgba="0.603922 0.603922 0.603922 1"/>
      </material>
    </visual>
    <collision>
      <origin xyz="-0.0147666 0.12609 0.00524528" rpy="1.5708 1.5708 0"/>
      <geometry>
        <mesh filename="package://gripper_description/meshes/fa3_link_2.stl"/>
      </geometry>
    </collision>
  </link>
  <!-- Link famr20100_soft_2 -->
  <link name="famr20100_soft_2">
    <inertial>
      <origin xyz="0 0 0" rpy="0 0 0"/>
      <mass value="1e-09"/>
      <inertia ixx="1e-09" ixy="0" ixz="0" iyy="1e-09" iyz="0" izz="1e-09"/>
    </inertial>
    <!-- Part famr20100_soft_2 -->
    <visual>
      <origin xyz="0.100828 -0.0875338 -0.00524528" rpy="-1.013 -1.5708 0"/>
      <geometry>
        <mesh filename="package://gripper_description/meshes/famr20100_soft_2.stl"/>
      </geometry>
      <material name="famr20100_soft_2_material">
        <color rgba="1 1 1 1"/>
      </material>
    </visual>
    <collision>
      <origin xyz="0.100828 -0.0875338 -0.00524528" rpy="-1.013 -1.5708 0"/>
      <geometry>
        <mesh filename="package://gripper_description/meshes/famr20100_soft_2.stl"/>
      </geometry>
    </collision>
  </link>
  <!-- Frame closing_link_1_3_2 (dummy link + fixed joint) -->
  <link name="closing_link_1_3_2">
    <origin xyz="0 0 0" rpy="0 -0 0"/>
    <inertial>
      <origin xyz="0 0 0" rpy="0 0 0"/>
      <mass value="1e-9"/>
      <inertia ixx="0" ixy="0" ixz="0" iyy="0" iyz="0" izz="0"/>
    </inertial>
  </link>
  <joint name="closing_link_1_3_2_frame" type="fixed">
    <origin xyz="0.00490177 -0.01939 0.008" rpy="-6.17872e-23 -2.78409e-23 0.557797"/>
    <parent link="famr20100_soft_2"/>
    <child link="closing_link_1_3_2"/>
    <axis xyz="0 0 0"/>
  </joint>
  <!-- Frame closing_link_1_3_2_z (dummy link + fixed joint) -->
  <link name="closing_link_1_3_2_z">
    <origin xyz="0 0 0" rpy="0 -0 0"/>
    <inertial>
      <origin xyz="0 0 0" rpy="0 0 0"/>
      <mass value="1e-9"/>
      <inertia ixx="0" ixy="0" ixz="0" iyy="0" iyz="0" izz="0"/>
    </inertial>
  </link>
  <joint name="closing_link_1_3_2_z_frame" type="fixed">
    <origin xyz="0.00490177 -0.01939 0.108" rpy="-6.17872e-23 -2.78409e-23 0.557797"/>
    <parent link="famr20100_soft_2"/>
    <child link="closing_link_1_3_2_z"/>
    <axis xyz="0 0 0"/>
  </joint>
  <!-- Joint from fa3_link_2 to famr20100_soft_2 -->
  <joint name="link_1_2" type="revolute">
    <origin xyz="-0.0539779 -0.00154554 0" rpy="3.14159 -1.46937e-39 0"/>
    <parent link="fa3_link_2"/>
    <child link="famr20100_soft_2"/>
    <axis xyz="0 0 1"/>
    <limit effort="10" velocity="10" lower="-3.141592653589793" upper="3.141592653589793"/>
  </joint>
  <!-- Joint from 42_motor_nut to fa3_link_2 -->
  <joint name="link_1_1" type="revolute">
    <origin xyz="-0.004 0.045 0.0043" rpy="1.5708 1.56379 -1.5708"/>
    <parent link="42_motor_nut"/>
    <child link="fa3_link_2"/>
    <axis xyz="0 0 1"/>
    <limit effort="10" velocity="10" lower="-3.141592653589793" upper="3.141592653589793"/>
  </joint>
  <!-- Link fa3_link -->
  <link name="fa3_link">
    <inertial>
      <origin xyz="0 0 0" rpy="0 0 0"/>
      <mass value="1e-09"/>
      <inertia ixx="1e-09" ixy="0" ixz="0" iyy="1e-09" iyz="0" izz="1e-09"/>
    </inertial>
    <!-- Part fa3_link -->
    <visual>
      <origin xyz="-0.00355171 0.0147666 0.0616035" rpy="3.14159 -0.523599 3.83739e-20"/>
      <geometry>
        <mesh filename="package://gripper_description/meshes/fa3_link.stl"/>
      </geometry>
      <material name="fa3_link_material">
        <color rgba="0.603922 0.603922 0.603922 1"/>
      </material>
    </visual>
    <collision>
      <origin xyz="-0.00355171 0.0147666 0.0616035" rpy="3.14159 -0.523599 3.83739e-20"/>
      <geometry>
        <mesh filename="package://gripper_description/meshes/fa3_link.stl"/>
      </geometry>
    </collision>
  </link>
  <!-- Link famr20100_soft_1 -->
  <link name="famr20100_soft_1">
    <inertial>
      <origin xyz="0 0 0" rpy="0 0 0"/>
      <mass value="1e-09"/>
      <inertia ixx="1e-09" ixy="0" ixz="0" iyy="1e-09" iyz="0" izz="1e-09"/>
    </inertial>
    <!-- Part famr20100_soft_1 -->
    <visual>
      <origin xyz="-0.00200617 0.0392113 -0.0616035" rpy="4.16642e-16 0.523599 -4.00617e-18"/>
      <geometry>
        <mesh filename="package://gripper_description/meshes/famr20100_soft_1.stl"/>
      </geometry>
      <material name="famr20100_soft_1_material">
        <color rgba="1 1 1 1"/>
      </material>
    </visual>
    <collision>
      <origin xyz="-0.00200617 0.0392113 -0.0616035" rpy="4.16642e-16 0.523599 -4.00617e-18"/>
      <geometry>
        <mesh filename="package://gripper_description/meshes/famr20100_soft_1.stl"/>
      </geometry>
    </collision>
  </link>
  <!-- Frame closing_link_2_3_1 (dummy link + fixed joint) -->
  <link name="closing_link_2_3_1">
    <origin xyz="0 0 0" rpy="0 -0 0"/>
    <inertial>
      <origin xyz="0 0 0" rpy="0 0 0"/>
      <mass value="1e-9"/>
      <inertia ixx="0" ixy="0" ixz="0" iyy="0" iyz="0" izz="0"/>
    </inertial>
  </link>
  <joint name="closing_link_2_3_1_frame" type="fixed">
    <origin xyz="0.0190455 -0.00610471 0.008" rpy="-3.14159 1.11022e-16 6.93889e-17"/>
    <parent link="famr20100_soft_1"/>
    <child link="closing_link_2_3_1"/>
    <axis xyz="0 0 0"/>
  </joint>
  <!-- Frame closing_link_2_3_1_z (dummy link + fixed joint) -->
  <link name="closing_link_2_3_1_z">
    <origin xyz="0 0 0" rpy="0 -0 0"/>
    <inertial>
      <origin xyz="0 0 0" rpy="0 0 0"/>
      <mass value="1e-9"/>
      <inertia ixx="0" ixy="0" ixz="0" iyy="0" iyz="0" izz="0"/>
    </inertial>
  </link>
  <joint name="closing_link_2_3_1_z_frame" type="fixed">
    <origin xyz="0.0190455 -0.00610471 -0.092" rpy="-3.14159 1.11022e-16 6.93889e-17"/>
    <parent link="famr20100_soft_1"/>
    <child link="closing_link_2_3_1_z"/>
    <axis xyz="0 0 0"/>
  </joint>
  <!-- Joint from fa3_link to famr20100_soft_1 -->
  <joint name="link_2_2" type="revolute">
    <origin xyz="-0.00154554 0.0539779 -3.81639e-17" rpy="-3.14159 -6.32827e-15 -0.557797"/>
    <parent link="fa3_link"/>
    <child link="famr20100_soft_1"/>
    <axis xyz="0 0 1"/>
    <limit effort="10" velocity="10" lower="-3.141592653589793" upper="3.141592653589793"/>
  </joint>
  <!-- Joint from 42_motor_nut to fa3_link -->
  <joint name="link_2_1" type="revolute">
    <origin xyz="-0.0369711 -0.0259641 0.0043" rpy="1.5708 -0.00701038 0.523599"/>
    <parent link="42_motor_nut"/>
    <child link="fa3_link"/>
    <axis xyz="0 0 1"/>
    <limit effort="10" velocity="10" lower="-3.141592653589793" upper="3.141592653589793"/>
  </joint>
  <!-- Link fa3_link_1 -->
  <link name="fa3_link_1">
    <inertial>
      <origin xyz="0 0 0" rpy="0 0 0"/>
      <mass value="1e-09"/>
      <inertia ixx="1e-09" ixy="0" ixz="0" iyy="1e-09" iyz="0" izz="1e-09"/>
    </inertial>
    <!-- Part fa3_link_1 -->
    <visual>
      <origin xyz="-0.0124616 -0.0147666 -0.0788487" rpy="5.08283e-16 -0.523599 -1.18922e-18"/>
      <geometry>
        <mesh filename="package://gripper_description/meshes/fa3_link_1.stl"/>
      </geometry>
      <material name="fa3_link_1_material">
        <color rgba="0.603922 0.603922 0.603922 1"/>
      </material>
    </visual>
    <collision>
      <origin xyz="-0.0124616 -0.0147666 -0.0788487" rpy="5.08283e-16 -0.523599 -1.18922e-18"/>
      <geometry>
        <mesh filename="package://gripper_description/meshes/fa3_link_1.stl"/>
      </geometry>
    </collision>
  </link>
  <!-- Link famr20100_soft -->
  <link name="famr20100_soft">
    <inertial>
      <origin xyz="0 0 0" rpy="0 0 0"/>
      <mass value="1e-09"/>
      <inertia ixx="1e-09" ixy="0" ixz="0" iyy="1e-09" iyz="0" izz="1e-09"/>
    </inertial>
    <!-- Part famr20100_soft -->
    <visual>
      <origin xyz="0.00887129 0.040682 -0.0708487" rpy="2.56395e-15 -0.523599 -0.557797"/>
      <geometry>
        <mesh filename="package://gripper_description/meshes/famr20100_soft.stl"/>
      </geometry>
      <material name="famr20100_soft_material">
        <color rgba="1 1 1 1"/>
      </material>
    </visual>
    <collision>
      <origin xyz="0.00887129 0.040682 -0.0708487" rpy="2.56395e-15 -0.523599 -0.557797"/>
      <geometry>
        <mesh filename="package://gripper_description/meshes/famr20100_soft.stl"/>
      </geometry>
    </collision>
  </link>
  <!-- Frame closing_link_3_3_2 (dummy link + fixed joint) -->
  <link name="closing_link_3_3_2">
    <origin xyz="0 0 0" rpy="0 -0 0"/>
    <inertial>
      <origin xyz="0 0 0" rpy="0 0 0"/>
      <mass value="1e-9"/>
      <inertia ixx="0" ixy="0" ixz="0" iyy="0" iyz="0" izz="0"/>
    </inertial>
  </link>
  <joint name="closing_link_3_3_2_frame" type="fixed">
    <origin xyz="-0.01939 0.00490177 0.008" rpy="4.996e-16 1.60982e-15 -2.12859"/>
    <parent link="famr20100_soft"/>
    <child link="closing_link_3_3_2"/>
    <axis xyz="0 0 0"/>
  </joint>
  <!-- Frame closing_link_3_3_2_z (dummy link + fixed joint) -->
  <link name="closing_link_3_3_2_z">
    <origin xyz="0 0 0" rpy="0 -0 0"/>
    <inertial>
      <origin xyz="0 0 0" rpy="0 0 0"/>
      <mass value="1e-9"/>
      <inertia ixx="0" ixy="0" ixz="0" iyy="0" iyz="0" izz="0"/>
    </inertial>
  </link>
  <joint name="closing_link_3_3_2_z_frame" type="fixed">
    <origin xyz="-0.01939 0.00490177 0.108" rpy="4.996e-16 1.60982e-15 -2.12859"/>
    <parent link="famr20100_soft"/>
    <child link="closing_link_3_3_2_z"/>
    <axis xyz="0 0 0"/>
  </joint>
  <!-- Joint from fa3_link_1 to famr20100_soft -->
  <joint name="link_3_2" type="revolute">
    <origin xyz="0.00154554 -0.0539779 -0.008" rpy="0 -0 0"/>
    <parent link="fa3_link_1"/>
    <child link="famr20100_soft"/>
    <axis xyz="0 0 1"/>
    <limit effort="10" velocity="10" lower="-3.141592653589793" upper="3.141592653589793"/>
  </joint>
  <!-- Joint from 42_motor_nut to fa3_link_1 -->
  <joint name="link_3_1" type="revolute">
    <origin xyz="0.0409711 -0.0190359 0.0043" rpy="-1.5708 0.00701038 -0.523599"/>
    <parent link="42_motor_nut"/>
    <child link="fa3_link_1"/>
    <axis xyz="0 0 1"/>
    <limit effort="10" velocity="10" lower="-3.141592653589793" upper="3.141592653589793"/>
  </joint>
  <!-- Joint from 42_step_motor to 42_motor_nut -->
  <joint name="slide" type="prismatic">
    <origin xyz="1.68268e-16 1.52656e-16 0.0255" rpy="0 -0 0"/>
    <parent link="42_step_motor"/>
    <child link="42_motor_nut"/>
    <axis xyz="0 0 1"/>
    <limit effort="10" velocity="10" lower="-0.01344" upper="-1.73472e-18"/>
  </joint>
</robot>
